Workbook

Sheet Resumen
C4: Resumen ejecutivo — Paquetes de personal
C6: Presupuesto por persona en dos etapas y escenarios de decisión desde el mes 7
C7: USD | Escenarios de repatriación excluyen costos únicos de transición hasta recibir cotizaciones
C9: INDICADORES DEL ESCENARIO SELECCIONADO
C10: Indicador | D10: Valor | E10: Interpretación | F10: Fuente | G10: Estado
C11: Costo anual original | D11: =Personal!M22 -> 2396800 | E11: Paquete anual fuente para 9 posiciones | F11: Tabla suministrada | G11: Referencia
C12: Etapa 1 — Consultor M1–M6 | D12: =Personal!U22 -> 1018200 | E12: Todos los componentes no fiscales prorrateados por seis meses | F12: Modelo | G12: Calculado
C13: Etapa 2 — Selección M7–M12 | D13: =Personal!AB22 -> 1150200 | E13: Paquete y ciudad elegidos por persona, más costos únicos | F13: Modelo | G13: Pendiente de decisiones
C14: Costo total Año 1 | D14: =Personal!AC22 -> 2168400 | E14: Etapa 1 + etapa 2 seleccionada | F14: Modelo | G14: Calculado
C15: Ahorro / (sobrecosto) vs. fuente | D15: =Personal!AD22 -> 228400 | E15: Costo anual original menos Año 1 seleccionado | F15: Modelo | G15: Calculado
C16: Run-rate anual desde M13 | D16: =Personal!AE22 -> 2300400 | E16: Costo anual recurrente posterior a la transición | F16: Modelo | G16: Calculado
C17: Personas con decisión pendiente | D17: =COUNTIF(Personal!AF12:AF20,"<>Completo") -> 2 | E17: Requieren paquete, ciudad o vivienda | F17: Modelo | G17: Acción requerida
C20: COMPARACIÓN DE ESCENARIOS — 9 POSICIONES
C21: Escenario | D21: Etapa 1 M1–M6 | E21: Etapa 2 M7–M12 | F21: Costo Año 1 | G21: Ahorro vs. fuente | H21: Run-rate M13+
C22: Selección actual por persona | D22: =Personal!U22 -> 1018200 | E22: =Personal!AB22 -> 1150200 | F22: =Personal!AC22 -> 2168400 | G22: =Personal!AD22 -> 228400 | H22: =Personal!AE22 -> 2300400
C23: Todos expatriados — empresa cubre impuesto | D23: 1045200 | E23: 1198400 | F23: 2243600 | G23: 153200 | H23: 2396800
C24: Todos repatriados — con housing; empleado paga impuesto | D24: =Personal!U22 -> 1018200 | E24: =(SUM(Personal!F12:F20)+SUM(Personal!G12:G20)+SUM(Personal!H12:H20)+SUM(Personal!J12:J20)+SUM(Personal!K12:K20)*Supuestos!$D$13+SUM(Personal!AJ12:AJ20))/12*Supuestos!$D$11 -> 1074200 | F24: =D24+E24 -> 2092400 | G24: =Personal!M22-F24 -> 304400 | H24: =E24/Supuestos!$D$11*12 -> 2148400
C25: Todos repatriados — sin housing; empleado paga impuesto | D25: =Personal!U22 -> 1018200 | E25: =(SUM(Personal!F12:F20)+SUM(Personal!H12:H20)+SUM(Personal!J12:J20)+SUM(Personal!K12:K20)*Supuestos!$D$13+SUM(Personal!AJ12:AJ20))/12*Supuestos!$D$11 -> 984200 | F25: =D25+E25 -> 2002400 | G25: =Personal!M22-F25 -> 394400 | H25: =E25/Supuestos!$D$11*12 -> 1968400
C28: DETALLE EJECUTIVO POR PERSONA
C29: Person | D29: Position | E29: Package M7+ | F29: City | G29: Stage 1 | H29: Stage 2 | I29: Year 1
C30: =Personal!E12 -> Martin del Castillo | D30: =Personal!D12 -> COO / PU General Manager | E30: =Personal!V12 -> Expatriado | F30: =Personal!W12 -> Por definir | G30: =Personal!U12 -> 226000 | H30: =Personal!AB12 -> 262000 | I30: =Personal!AC12 -> 488000
C31: =Personal!E13 -> Juan Conde | D31: =Personal!D13 -> EPCM & Engineering Manager | E31: =Personal!V13 -> Repatriado | F31: =Personal!W13 -> Maracaibo | G31: =Personal!U13 -> 141000 | H31: =Personal!AB13 -> 171000 | I31: =Personal!AC13 -> 312000
C32: =Personal!E14 -> Alexander Stulme | D32: =Personal!D14 -> Drilling & Well Services Manager | E32: =Personal!V14 -> Repatriado | F32: =Personal!W14 -> Maracaibo | G32: =Personal!U14 -> 123000 | H32: =Personal!AB14 -> 135000 | I32: =Personal!AC14 -> 258000
C33: =Personal!E15 -> Félix Valderrama | D33: =Personal!D15 -> Operations & Maintenance Manager | E33: =Personal!V15 -> Repatriado | F33: =Personal!W15 -> Maracaibo | G33: =Personal!U15 -> 141000 | H33: =Personal!AB15 -> 171000 | I33: =Personal!AC15 -> 312000
C34: =Personal!E16 -> Alan McKeon | D34: =Personal!D16 -> Technical Manager (Geosciences) | E34: =Personal!V16 -> Expatriado | F34: =Personal!W16 -> Maracaibo | G34: =Personal!U16 -> 123000 | H34: =Personal!AB16 -> 135000 | I34: =Personal!AC16 -> 258000
C35: =Personal!E17 -> JJI | D35: =Personal!D17 -> Reservoir Engineer | E35: =Personal!V17 -> Remote | F35: =Personal!W17 -> Remoto | G35: =Personal!U17 -> 60000 | H35: =Personal!AB17 -> 60000 | I35: =Personal!AC17 -> 120000
C36: =Personal!E18 -> Marcelo Dantas | D36: =Personal!D18 -> Rig Company Man | E36: =Personal!V18 -> On rotation | F36: =Personal!W18 -> Por definir | G36: =Personal!U18 -> 123000 | H36: =Personal!AB18 -> 141000 | I36: =Personal!AC18 -> 264000
C37: =Personal!E19 -> Jose Miguel | D37: =Personal!D19 -> Planning & PMO | E37: =Personal!V19 -> Local | F37: =Personal!W19 -> Maracaibo | G37: =Personal!U19 -> 37600 | H37: =Personal!AB19 -> 37600 | I37: =Personal!AC19 -> 75200
C38: =Personal!E20 -> TBD | D38: =Personal!D20 -> Operations Support | E38: =Personal!V20 -> Local | F38: =Personal!W20 -> Por definir | G38: =Personal!U20 -> 43600 | H38: =Personal!AB20 -> 37600 | I38: =Personal!AC20 -> 81200
C41: DECISIONES NECESARIAS
C42: 1. Designar por persona si desde el mes 7 será Repatriado o Expatriado.
C43: 2. Confirmar ciudad de residencia: Caracas, Maracaibo u otra.
C44: 3. Validar la política inicial: Caracas con housing; Maracaibo sin housing para repatriados.
C45: 4. Confirmar por escrito que el expatriado recibe protección / gross-up fiscal y que el repatriado asume su impuesto personal.
C46: 5. Incorporar costos únicos cotizados y obtener dictamen escrito de inmigración, laboral y fiscal.
C49: PUENTE DE COSTO — ESCENARIO PREVIO VS. PAQUETES INDIVIDUALES
C50: Person | D50: Previous Expat Year 1 | E50: Selected Year 1 | F50: Savings / (Overcost) | G50: Reason
C51: Martin del Castillo | D51: 488000 | E51: =Personal!AC12 -> 488000 | F51: =D51-E51 -> 0 | G51: Sin cambio frente al paquete previo.
C52: Juan Conde | D52: 303600 | E52: =Personal!AC13 -> 312000 | F52: =D52-E52 -> -8400 | G52: Ahorro de impuesto y home leave compensado por bonus de 4 meses; neto: sobrecosto.
C53: Alexander Stulme | D53: 264000 | E53: =Personal!AC14 -> 258000 | F53: =D53-E53 -> 6000 | G53: Sin housing, impuesto ni home leave; el bonus absorbe la mayor parte del ahorro.
...

Sheet Supuestos
C4: Supuestos y política de paquetes
C6: Variables editables para el modelo de compensación en dos etapas
C7: USD, salvo indicación contraria | Celdas azules = entradas editables
C9: SUPUESTOS DE DURACIÓN Y FISCALIDAD
C10: Meses de la etapa 1 — Consultor | D10: 6
C11: Meses de la etapa 2 — Repatriado / Expatriado | D11: 6
C12: Factor de Tax & Social en la etapa 1 | D12: 0
C13: Factor de Tax & Social pagado por la empresa — Repatriado M7+ | D13: 0
C14: Factor de Tax & Social pagado por la empresa — Expatriado M7+ | D14: 1
C17: POLÍTICA AUTOMÁTICA DE VIVIENDA POR CIUDAD
C18: Ciudad | D18: Housing automático | E18: Racional presupuestario | F18: Editable
C19: Caracas | D19: Sí | E19: Se presupone allowance si la persona debe residir en Caracas. | F19: Sí
C20: Maracaibo | D20: No | E20: Se presupone sin allowance para repatriados radicados en Maracaibo. | F20: Sí
C21: Otro | D21: Sí | E21: Enfoque conservador hasta confirmar alojamiento. | F21: Sí
C22: Por definir | D22: Por definir | E22: El cálculo conservador incluye vivienda si el paquete es repatriado. | F22: Sí
C25: COMPONENTES DE CADA PAQUETE
C26: Componente | D26: Consultor M1–M6 | E26: Repatriado M7+ | F26: Expatriado M7+ | G26: Criterio | H26: Observación
C27: Compensación base | D27: Sí — honorario prorrateado | E27: Sí — salario local | F27: Sí — salario base | G27: Valor fuente por persona | H27: El modelo usa 6/12 del importe anual en cada etapa.
C28: Housing | D28: Sí | E28: Condicional por ciudad / override | F28: Sí | G28: Valor fuente por persona | H28: Caracas = Sí y Maracaibo = No como política inicial editable.
C29: Seguro médico | D29: Sí | E29: Sí | F29: Sí | G29: Valor fuente por persona | H29: Prorrateado por meses.
C30: Home leave | D30: Sí | E30: No | F30: Sí | G30: Valor fuente por persona | H30: Se elimina en el paquete de repatriado.
C31: Vehículo | D31: Sí | E31: Sí | F31: Sí | G31: Valor fuente por persona | H31: Prorrateado por meses.
C32: Impuesto del país de trabajo | D32: No cubierto en el modelo | E32: Lo asume el empleado | F32: Lo cubre / neutraliza la empresa | G32: Factores editables | H32: Repatriado: factor empresa 0%; expatriado: factor empresa 100% por defecto.
C33: Costos únicos de transición | D33: No incluidos | E33: Entrada individual | F33: Entrada individual | G33: Cotizaciones pendientes | H33: El modelo parte de $0 hasta recibir presupuestos de viaje, mudanza, permisos y alojamiento temporal.
C36: ADVERTENCIA DE CUMPLIMIENTO
C37: El tratamiento de los meses 1–6 como consultoría sin Tax & Social venezolano es un supuesto presupuestario indicado por la gerencia, no una conclusión jurídica. La condición migratoria de turista no acredita por sí sola autorización para trabajar ni exención fiscal. Antes de implementar el esquema, se requiere validación escrita de asesores venezolanos de inmigración, derecho laboral, nómina y tributos.

Sheet Personal
C4: Modelo de paquetes por persona
C6: Etapa 1: seis meses como consultor | Etapa 2: repatriado o expatriado desde el mes 7
C7: USD | Celdas azules = datos fuente o decisiones editables; fórmulas verdes = vínculos a Supuestos
C9: BASE DE COMPENSACIÓN Y CÁLCULO POR PERSONA
C11: # | D11: Position | E11: Person | F11: Base Salary Annual | G11: Housing Annual | H11: Medical Annual | I11: Home Leave Annual | J11: Vehicle Annual | K11: Tax & Social Annual | L11: Calculated Annual | M11: Stated Annual | N11: Variance | O11: Consulting Fee M1–M6 | P11: Housing M1–M6 | Q11: Medical M1–M6 | R11: Home Leave M1–M6 | S11: Vehicle M1–M6 | T11: Tax & Social M1–M6 | U11: Stage 1 Total | V11: Package M7+ | W11: City M7+ | X11: Housing Override | Y11: Housing Final | Z11: One-time Transition | AA11: Stage 2 Recurring M7–M12 | AB11: Stage 2 Total | AC11: Year 1 Total | AD11: Savings vs. Source | AE11: Annual Run-rate M13+ | AF11: Decision Status | AG11: Monthly Cost M1–M6 | AH11: Selected Monthly M7+ | AI11: M7 incl. Transition | AJ11: Annual Bonus M7+ | AK11: Stock Options Annual Value (TBD) | AL11: Vacation Days | AM11: Housing M7+ Annual Override
C12: 1 | D12: COO / PU General Manager | E12: Martin del Castillo | F12: 360000 | G12: 36000 | H12: 12000 | I12: 20000 | J12: 24000 | K12: 72000 | L12: =SUM(F12:K12) -> 524000 | M12: 524000 | N12: =L12-M12 -> 0 | O12: =F12/12*Supuestos!$D$10 -> 180000 | P12: =G12/12*Supuestos!$D$10 -> 18000 | Q12: =H12/12*Supuestos!$D$10 -> 6000 | R12: =I12/12*Supuestos!$D$10 -> 10000 | S12: =J12/12*Supuestos!$D$10 -> 12000 | T12: =K12/12*Supuestos!$D$10*Supuestos!$D$12 -> 0 | U12: =SUM(O12:T12) -> 226000 | V12: Expatriado | W12: Por definir | X12: Automático | Y12: =IF(X12="Automático",IF(W12="Caracas","Sí",IF(W12="Maracaibo","No",IF(W12="Otro","Sí","Por definir"))),X12) -> Por definir | Z12: 0 | AA12: =IF(V12="Expatriado",F12+IF(AM12>0,AM12,G12)+H12+I12+J12+K12*Supuestos!$D$14,IF(V12="Repatriado",F12+H12+J12+K12*Supuestos!$D$13+IF(Y12="No",0,IF(AM12>0,AM12,G12))+AJ12,IF(V12="Remote",F12,IF(V12="Local",F12+H12+J12+K12*Supuestos!$D$13+IF(Y12="No",0,IF(AM12>0,AM12,G12))+AJ12,IF(V12="On rotation",F12+IF(AM12>0,AM12,G12)+H12+I12+J12+K12*Supuestos!$D$14,0)))))/12*Supuestos!$D$11 -> 262000 | AB12: =AA12+Z12 -> 262000 | AC12: =U12+AB12 -> 488000 | AD12: =M12-AC12 -> 36000 | AE12: =IF(V12="Expatriado",F12+IF(AM12>0,AM12,G12)+H12+I12+J12+K12*Supuestos!$D$14,IF(V12="Repatriado",F12+H12+J12+K12*Supuestos!$D$13+IF(Y12="No",0,IF(AM12>0,AM12,G12))+AJ12,IF(V12="Remote",F12,IF(V12="Local",F12+H12+J12+K12*Supuestos!$D$13+IF(Y12="No",0,IF(AM12>0,AM12,G12))+AJ12,IF(V12="On rotation",F12+IF(AM12>0,AM12,G12)+H12+I12+J12+K12*Supuestos!$D$14,0))))) -> 524000 | AF12: =IF(V12="Por definir","Definir paquete",IF(OR(V12="Remote",V12="On rotation"),"Completo",IF(W12="Por definir","Definir ciudad",IF(AND(OR(V12="Repatriado",V12="Local"),Y12="Por definir"),"Definir vivienda","Completo")))) -> Definir ciudad | AG12: =U12/Supuestos!$D$10 -> 37666.667 | AH12: =AA12/Supuestos!$D$11 -> 43666.667 | AI12: =AH12+Z12 -> 43666.667 | AJ12: =0 -> 0 | AK12: =0 -> 0 | AL12: =0 -> 0 | AM12: =0 -> 0
C13: 2 | D13: EPCM & Engineering Manager | E13: Juan Conde | F13: 216000 | G13: 24000 | H13: 12000 | I13: 12000 | J13: 18000 | K13: 43200 | L13: =SUM(F13:K13) -> 325200 | M13: 325200 | N13: =L13-M13 -> 0 | O13: =F13/12*Supuestos!$D$10 -> 108000 | P13: =G13/12*Supuestos!$D$10 -> 12000 | Q13: =H13/12*Supuestos!$D$10 -> 6000 | R13: =I13/12*Supuestos!$D$10 -> 6000 | S13: =J13/12*Supuestos!$D$10 -> 9000 | T13: =K13/12*Supuestos!$D$10*Supuestos!$D$12 -> 0 | U13: =SUM(O13:T13) -> 141000 | V13: Repatriado | W13: Maracaibo | X13: Automático | Y13: =IF(X13="Automático",IF(W13="Caracas","No",IF(W13="Maracaibo","Sí",IF(W13="Otro","Sí","Por definir"))),X13) -> Sí | Z13: 0 | AA13: =IF(V13="Expatriado",F13+IF(AM13>0,AM13,G13)+H13+I13+J13+K13*Supuestos!$D$14,IF(V13="Repatriado",F13+H13+J13+K13*Supuestos!$D$13+IF(Y13="No",0,IF(AM13>0,AM13,G13))+AJ13,IF(V13="Remote",F13,IF(V13="Local",F13+H13+J13+K13*Supuestos!$D$13+IF(Y13="No",0,IF(AM13>0,AM13,G13))+AJ13,IF(V13="On rotation",F13+IF(AM13>0,AM13,G13)+H13+I13+J13+K13*Supuestos!$D$14,0)))))/12*Supuestos!$D$11 -> 171000 | AB13: =AA13+Z13 -> 171000 | AC13: =U13+AB13 -> 312000 | AD13: =M13-AC13 -> 13200 | AE13: =IF(V13="Expatriado",F13+IF(AM13>0,AM13,G13)+H13+I13+J13+K13*Supuestos!$D$14,IF(V13="Repatriado",F13+H13+J13+K13*Supuestos!$D$13+IF(Y13="No",0,IF(AM13>0,AM13,G13))+AJ13,IF(V13="Remote",F13,IF(V13="Local",F13+H13+J13+K13*Supuestos!$D$13+IF(Y13="No",0,IF(AM13>0,AM13,G13))+AJ13,IF(V13="On rotation",F13+IF(AM13>0,AM13,G13)+H13+I13+J13+K13*Supuestos!$D$14,0))))) -> 342000 | AF13: =IF(V13="Por definir","Definir paquete",IF(OR(V13="Remote",V13="On rotation"),"Completo",IF(W13="Por definir","Definir ciudad",IF(AND(OR(V13="Repatriado",V13="Local"),Y13="Por definir"),"Definir vivienda","Completo")))) -> Completo | AG13: =U13/Supuestos!$D$10 -> 23500 | AH13: =AA13/Supuestos!$D$11 -> 28500 | AI13: =AH13+Z13 -> 28500 | AJ13: =F13*4/12 -> 72000 | AK13: TBD | AL13: 13 | AM13: =0 -> 0
C14: 3 | D14: Drilling & Well Services Manager | E14: Alexander Stulme | F14: 180000 | G14: 24000 | H14: 12000 | I14: 12000 | J14: 18000 | K14: 36000 | L14: =SUM(F14:K14) -> 282000 | M14: 282000 | N14: =L14-M14 -> 0 | O14: =F14/12*Supuestos!$D$10 -> 90000 | P14: =G14/12*Supuestos!$D$10 -> 12000 | Q14: =H14/12*Supuestos!$D$10 -> 6000 | R14: =I14/12*Supuestos!$D$10 -> 6000 | S14: =J14/12*Supuestos!$D$10 -> 9000 | T14: =K14/12*Supuestos!$D$10*Supuestos!$D$12 -> 0 | U14: =SUM(O14:T14) -> 123000 | V14: Repatriado | W14: Maracaibo | X14: No | Y14: =IF(X14="Automático",IF(W14="Caracas","Sí",IF(W14="Maracaibo","No",IF(W14="Otro","Sí","Por definir"))),X14) -> No | Z14: 0 | AA14: =IF(V14="Expatriado",F14+IF(AM14>0,AM14,G14)+H14+I14+J14+K14*Supuestos!$D$14,IF(V14="Repatriado",F14+H14+J14+K14*Supuestos!$D$13+IF(Y14="No",0,IF(AM14>0,AM14,G14))+AJ14,IF(V14="Remote",F14,IF(V14="Local",F14+H14+J14+K14*Supuestos!$D$13+IF(Y14="No",0,IF(AM14>0,AM14,G14))+AJ14,IF(V14="On rotation",F14+IF(AM14>0,AM14,G14)+H14+I14+J14+K14*Supuestos!$D$14,0)))))/12*Supuestos!$D$11 -> 135000 | AB14: =AA14+Z14 -> 135000 | AC14: =U14+AB14 -> 258000 | AD14: =M14-AC14 -> 24000 | AE14: =IF(V14="Expatriado",F14+IF(AM14>0,AM14,G14)+H14+I14+J14+K14*Supuestos!$D$14,IF(V14="Repatriado",F14+H14+J14+K14*Supuestos!$D$13+IF(Y14="No",0,IF(AM14>0,AM14,G14))+AJ14,IF(V14="Remote",F14,IF(V14="Local",F14+H14+J14+K14*Supuestos!$D$13+IF(Y14="No",0,IF(AM14>0,AM14,G14))+AJ14,IF(V14="On rotation",F14+IF(AM14>0,AM14,G14)+H14+I14+J14+K14*Supuestos!$D$14,0))))) -> 270000 | AF14: =IF(V14="Por definir","Definir paquete",IF(OR(V14="Remote",V14="On rotation"),"Completo",IF(W14="Por definir","Definir ciudad",IF(AND(OR(V14="Repatriado",V14="Local"),Y14="Por definir"),"Definir vivienda","Completo")))) -> Completo | AG14: =U14/Supuestos!$D$10 -> 20500 | AH14: =AA14/Supuestos!$D$11 -> 22500 | AI14: =AH14+Z14 -> 22500 | AJ14: =F14*4/12 -> 60000 | AK14: TBD | AL14: 13 | AM14: =0 -> 0
C15: 4 | D15: Operations & Maintenance Manager | E15: Félix Valderrama | F15: 216000 | G15: 24000 | H15: 12000 | I15: 12000 | J15: 18000 | K15: 43200 | L15: =SUM(F15:K15) -> 325200 | M15: 325200 | N15: =L15-M15 -> 0 | O15: =F15/12*Supuestos!$D$10 -> 108000 | P15: =G15/12*Supuestos!$D$10 -> 12000 | Q15: =H15/12*Supuestos!$D$10 -> 6000 | R15: =I15/12*Supuestos!$D$10 -> 6000 | S15: =J15/12*Supuestos!$D$10 -> 9000 | T15: =K15/12*Supuestos!$D$10*Supuestos!$D$12 -> 0 | U15: =SUM(O15:T15) -> 141000 | V15: Repatriado | W15: Maracaibo | X15: Automático | Y15: =IF(X15="Automático",IF(W15="Caracas","No",IF(W15="Maracaibo","Sí",IF(W15="Otro","Sí","Por definir"))),X15) -> Sí | Z15: 0 | AA15: =IF(V15="Expatriado",F15+IF(AM15>0,AM15,G15)+H15+I15+J15+K15*Supuestos!$D$14,IF(V15="Repatriado",F15+H15+J15+K15*Supuestos!$D$13+IF(Y15="No",0,IF(AM15>0,AM15,G15))+AJ15,IF(V15="Remote",F15,IF(V15="Local",F15+H15+J15+K15*Supuestos!$D$13+IF(Y15="No",0,IF(AM15>0,AM15,G15))+AJ15,IF(V15="On rotation",F15+IF(AM15>0,AM15,G15)+H15+I15+J15+K15*Supuestos!$D$14,0)))))/12*Supuestos!$D$11 -> 171000 | AB15: =AA15+Z15 -> 171000 | AC15: =U15+AB15 -> 312000 | AD15: =M15-AC15 -> 13200 | AE15: =IF(V15="Expatriado",F15+IF(AM15>0,AM15,G15)+H15+I15+J15+K15*Supuestos!$D$14,IF(V15="Repatriado",F15+H15+J15+K15*Supuestos!$D$13+IF(Y15="No",0,IF(AM15>0,AM15,G15))+AJ15,IF(V15="Remote",F15,IF(V15="Local",F15+H15+J15+K15*Supuestos!$D$13+IF(Y15="No",0,IF(AM15>0,AM15,G15))+AJ15,IF(V15="On rotation",F15+IF(AM15>0,AM15,G15)+H15+I15+J15+K15*Supuestos!$D$14,0))))) -> 342000 | AF15: =IF(V15="Por definir","Definir paquete",IF(OR(V15="Remote",V15="On rotation"),"Completo",IF(W15="Por definir","Definir ciudad",IF(AND(OR(V15="Repatriado",V15="Local"),Y15="Por definir"),"Definir vivienda","Completo")))) -> Completo | AG15: =U15/Supuestos!$D$10 -> 23500 | AH15: =AA15/Supuestos!$D$11 -> 28500 | AI15: =AH15+Z15 -> 28500 | AJ15: =F15*4/12 -> 72000 | AK15: TBD | AL15: 13 | AM15: =0 -> 0
C16: 5 | D16: Technical Manager (Geosciences) | E16: Alan McKeon | F16: 180000 | G16: 24000 | H16: 12000 | I16: 12000 | J16: 18000 | K16: 36000 | L16: =SUM(F16:K16) -> 282000 | M16: 282000 | N16: =L16-M16 -> 0 | O16: =F16/12*Supuestos!$D$10 -> 90000 | P16: =G16/12*Supuestos!$D$10 -> 12000 | Q16: =H16/12*Supuestos!$D$10 -> 6000 | R16: =I16/12*Supuestos!$D$10 -> 6000 | S16: =J16/12*Supuestos!$D$10 -> 9000 | T16: =K16/12*Supuestos!$D$10*Supuestos!$D$12 -> 0 | U16: =SUM(O16:T16) -> 123000 | V16: Expatriado | W16: Maracaibo | X16: Sí | Y16: =IF(X16="Automático",IF(W16="Caracas","Sí",IF(W16="Maracaibo","No",IF(W16="Otro","Sí","Por definir"))),X16) -> Sí | Z16: 0 | AA16: =IF(V16="Expatriado",F16+IF(AM16>0,AM16,G16)+H16+I16+J16+K16*Supuestos!$D$14,IF(V16="Repatriado",F16+H16+J16+K16*Supuestos!$D$13+IF(Y16="No",0,IF(AM16>0,AM16,G16))+AJ16,IF(V16="Remote",F16,IF(V16="Local",F16+H16+J16+K16*Supuestos!$D$13+IF(Y16="No",0,IF(AM16>0,AM16,G16))+AJ16,IF(V16="On rotation",F16+IF(AM16>0,AM16,G16)+H16+I16+J16+K16*Supuestos!$D$14,0)))))/12*Supuestos!$D$11 -> 135000 | AB16: =AA16+Z16 -> 135000 | AC16: =U16+AB16 -> 258000 | AD16: =M16-AC16 -> 24000 | AE16: =IF(V16="Expatriado",F16+IF(AM16>0,AM16,G16)+H16+I16+J16+K16*Supuestos!$D$14,IF(V16="Repatriado",F16+H16+J16+K16*Supuestos!$D$13+IF(Y16="No",0,IF(AM16>0,AM16,G16))+AJ16,IF(V16="Remote",F16,IF(V16="Local",F16+H16+J16+K16*Supuestos!$D$13+IF(Y16="No",0,IF(AM16>0,AM16,G16))+AJ16,IF(V16="On rotation",F16+IF(AM16>0,AM16,G16)+H16+I16+J16+K16*Supuestos!$D$14,0))))) -> 270000 | AF16: =IF(V16="Por definir","Definir paquete",IF(OR(V16="Remote",V16="On rotation"),"Completo",IF(W16="Por definir","Definir ciudad",IF(AND(OR(V16="Repatriado",V16="Local"),Y16="Por definir"),"Definir vivienda","Completo")))) -> Completo | AG16: =U16/Supuestos!$D$10 -> 20500 | AH16: =AA16/Supuestos!$D$11 -> 22500 | AI16: =AH16+Z16 -> 22500 | AJ16: =0 -> 0 | AK16: =0 -> 0 | AL16: =0 -> 0 | AM16: 12000
C17: 6 | D17: Reservoir Engineer | E17: JJI | F17: 120000 | G17: 0 | H17: 0 | I17: 0 | J17: 0 | K17: 0 | L17: =SUM(F17:K17) -> 120000 | M17: 194000 | N17: =L17-M17 -> -74000 | O17: =F17/12*Supuestos!$D$10 -> 60000 | P17: =G17/12*Supuestos!$D$10 -> 0 | Q17: =H17/12*Supuestos!$D$10 -> 0 | R17: =I17/12*Supuestos!$D$10 -> 0 | S17: =J17/12*Supuestos!$D$10 -> 0 | T17: =K17/12*Supuestos!$D$10*Supuestos!$D$12 -> 0 | U17: =SUM(O17:T17) -> 60000 | V17: Remote | W17: Remoto | X17: No | Y17: =IF(X17="Automático",IF(W17="Caracas","Sí",IF(W17="Maracaibo","No",IF(W17="Otro","Sí","Por definir"))),X17) -> No | Z17: 0 | AA17: =IF(V17="Expatriado",F17+IF(AM17>0,AM17,G17)+H17+I17+J17+K17*Supuestos!$D$14,IF(V17="Repatriado",F17+H17+J17+K17*Supuestos!$D$13+IF(Y17="No",0,IF(AM17>0,AM17,G17))+AJ17,IF(V17="Remote",F17,IF(V17="Local",F17+H17+J17+K17*Supuestos!$D$13+IF(Y17="No",0,IF(AM17>0,AM17,G17))+AJ17,IF(V17="On rotation",F17+IF(AM17>0,AM17,G17)+H17+I17+J17+K17*Supuestos!$D$14,0)))))/12*Supuestos!$D$11 -> 60000 | AB17: =AA17+Z17 -> 60000 | AC17: =U17+AB17 -> 120000 | AD17: =M17-AC17 -> 74000 | AE17: =IF(V17="Expatriado",F17+IF(AM17>0,AM17,G17)+H17+I17+J17+K17*Supuestos!$D$14,IF(V17="Repatriado",F17+H17+J17+K17*Supuestos!$D$13+IF(Y17="No",0,IF(AM17>0,AM17,G17))+AJ17,IF(V17="Remote",F17,IF(V17="Local",F17+H17+J17+K17*Supuestos!$D$13+IF(Y17="No",0,IF(AM17>0,AM17,G17))+AJ17,IF(V17="On rotation",F17+IF(AM17>0,AM17,G17)+H17+I17+J17+K17*Supuestos!$D$14,0))))) -> 120000 | AF17: =IF(V17="Por definir","Definir paquete",IF(OR(V17="Remote",V17="On rotation"),"Completo",IF(W17="Por definir","Definir ciudad",IF(AND(OR(V17="Repatriado",V17="Local"),Y17="Por definir"),"Definir vivienda","Completo")))) -> Completo | AG17: =U17/Supuestos!$D$10 -> 10000 | AH17: =AA17/Supuestos!$D$11 -> 10000 | AI17: =AH17+Z17 -> 10000 | AJ17: =0 -> 0 | AK17: =0 -> 0 | AL17: =0 -> 0 | AM17: =0 -> 0
C18: 7 | D18: Rig Company Man | E18: Marcelo Dantas | F18: 180000 | G18: 24000 | H18: 12000 | I18: 12000 | J18: 18000 | K18: 36000 | L18: =SUM(F18:K18) -> 282000 | M18: 282000 | N18: =L18-M18 -> 0 | O18: =F18/12*Supuestos!$D$10 -> 90000 | P18: =G18/12*Supuestos!$D$10 -> 12000 | Q18: =H18/12*Supuestos!$D$10 -> 6000 | R18: =I18/12*Supuestos!$D$10 -> 6000 | S18: =J18/12*Supuestos!$D$10 -> 9000 | T18: =K18/12*Supuestos!$D$10*Supuestos!$D$12 -> 0 | U18: =SUM(O18:T18) -> 123000 | V18: On rotation | W18: Por definir | X18: Automático | Y18: =IF(X18="Automático",IF(W18="Caracas","Sí",IF(W18="Maracaibo","No",IF(W18="Otro","Sí","Por definir"))),X18) -> Por definir | Z18: 0 | AA18: =IF(V18="Expatriado",F18+IF(AM18>0,AM18,G18)+H18+I18+J18+K18*Supuestos!$D$14,IF(V18="Repatriado",F18+H18+J18+K18*Supuestos!$D$13+IF(Y18="No",0,IF(AM18>0,AM18,G18))+AJ18,IF(V18="Remote",F18,IF(V18="Local",F18+H18+J18+K18*Supuestos!$D$13+IF(Y18="No",0,IF(AM18>0,AM18,G18))+AJ18,IF(V18="On rotation",F18+IF(AM18>0,AM18,G18)+H18+I18+J18+K18*Supuestos!$D$14,0)))))/12*Supuestos!$D$11 -> 141000 | AB18: =AA18+Z18 -> 141000 | AC18: =U18+AB18 -> 264000 | AD18: =M18-AC18 -> 18000 | AE18: =IF(V18="Expatriado",F18+IF(AM18>0,AM18,G18)+H18+I18+J18+K18*Supuestos!$D$14,IF(V18="Repatriado",F18+H18+J18+K18*Supuestos!$D$13+IF(Y18="No",0,IF(AM18>0,AM18,G18))+AJ18,IF(V18="Remote",F18,IF(V18="Local",F18+H18+J18+K18*Supuestos!$D$13+IF(Y18="No",0,IF(AM18>0,AM18,G18))+AJ18,IF(V18="On rotation",F18+IF(AM18>0,AM18,G18)+H18+I18+J18+K18*Supuestos!$D$14,0))))) -> 282000 | AF18: =IF(V18="Por definir","Definir paquete",IF(OR(V18="Remote",V18="On rotation"),"Completo",IF(W18="Por definir","Definir ciudad",IF(AND(OR(V18="Repatriado",V18="Local"),Y18="Por definir"),"Definir vivienda","Completo")))) -> Completo | AG18: =U18/Supuestos!$D$10 -> 20500 | AH18: =AA18/Supuestos!$D$11 -> 23500 | AI18: =AH18+Z18 -> 23500 | AJ18: =0 -> 0 | AK18: =0 -> 0 | AL18: =0 -> 0 | AM18: =0 -> 0
C19: 8 | D19: Planning & PMO | E19: Jose Miguel | F19: 48000 | G19: 12000 | H19: 8000 | I19: 0 | J19: 7200 | K19: 12000 | L19: =SUM(F19:K19) -> 87200 | M19: 87200 | N19: =L19-M19 -> 0 | O19: =F19/12*Supuestos!$D$10 -> 24000 | P19: =G19/12*Supuestos!$D$10 -> 6000 | Q19: =H19/12*Supuestos!$D$10 -> 4000 | R19: =I19/12*Supuestos!$D$10 -> 0 | S19: =J19/12*Supuestos!$D$10 -> 3600 | T19: =K19/12*Supuestos!$D$10*Supuestos!$D$12 -> 0 | U19: =SUM(O19:T19) -> 37600 | V19: Local | W19: Maracaibo | X19: Sí | Y19: =IF(X19="Automático",IF(W19="Caracas","Sí",IF(W19="Maracaibo","No",IF(W19="Otro","Sí","Por definir"))),X19) -> Sí | Z19: 0 | AA19: =IF(V19="Expatriado",F19+IF(AM19>0,AM19,G19)+H19+I19+J19+K19*Supuestos!$D$14,IF(V19="Repatriado",F19+H19+J19+K19*Supuestos!$D$13+IF(Y19="No",0,IF(AM19>0,AM19,G19))+AJ19,IF(V19="Remote",F19,IF(V19="Local",F19+H19+J19+K19*Supuestos!$D$13+IF(Y19="No",0,IF(AM19>0,AM19,G19))+AJ19,IF(V19="On rotation",F19+IF(AM19>0,AM19,G19)+H19+I19+J19+K19*Supuestos!$D$14,0)))))/12*Supuestos!$D$11 -> 37600 | AB19: =AA19+Z19 -> 37600 | AC19: =U19+AB19 -> 75200 | AD19: =M19-AC19 -> 12000 | AE19: =IF(V19="Expatriado",F19+IF(AM19>0,AM19,G19)+H19+I19+J19+K19*Supuestos!$D$14,IF(V19="Repatriado",F19+H19+J19+K19*Supuestos!$D$13+IF(Y19="No",0,IF(AM19>0,AM19,G19))+AJ19,IF(V19="Remote",F19,IF(V19="Local",F19+H19+J19+K19*Supuestos!$D$13+IF(Y19="No",0,IF(AM19>0,AM19,G19))+AJ19,IF(V19="On rotation",F19+IF(AM19>0,AM19,G19)+H19+I19+J19+K19*Supuestos!$D$14,0))))) -> 75200 | AF19: =IF(V19="Por definir","Definir paquete",IF(OR(V19="Remote",V19="On rotation"),"Completo",IF(W19="Por definir","Definir ciudad",IF(AND(OR(V19="Repatriado",V19="Local"),Y19="Por definir"),"Definir vivienda","Completo")))) -> Completo | AG19: =U19/Supuestos!$D$10 -> 6266.6667 | AH19: =AA19/Supuestos!$D$11 -> 6266.6667 | AI19: =AH19+Z19 -> 6266.6667 | AJ19: =0 -> 0 | AK19: =0 -> 0 | AL19: =0 -> 0 | AM19: =0 -> 0
C20: 9 | D20: Operations Support | E20: TBD | F20: 48000 | G20: 12000 | H20: 8000 | I20: 12000 | J20: 7200 | K20: 8000 | L20: =SUM(F20:K20) -> 95200 | M20: 95200 | N20: =L20-M20 -> 0 | O20: =F20/12*Supuestos!$D$10 -> 24000 | P20: =G20/12*Supuestos!$D$10 -> 6000 | Q20: =H20/12*Supuestos!$D$10 -> 4000 | R20: =I20/12*Supuestos!$D$10 -> 6000 | S20: =J20/12*Supuestos!$D$10 -> 3600 | T20: =K20/12*Supuestos!$D$10*Supuestos!$D$12 -> 0 | U20: =SUM(O20:T20) -> 43600 | V20: Local | W20: Por definir | X20: Automático | Y20: =IF(X20="Automático",IF(W20="Caracas","Sí",IF(W20="Maracaibo","No",IF(W20="Otro","Sí","Por definir"))),X20) -> Por definir | Z20: 0 | AA20: =IF(V20="Expatriado",F20+IF(AM20>0,AM20,G20)+H20+I20+J20+K20*Supuestos!$D$14,IF(V20="Repatriado",F20+H20+J20+K20*Supuestos!$D$13+IF(Y20="No",0,IF(AM20>0,AM20,G20))+AJ20,IF(V20="Remote",F20,IF(V20="Local",F20+H20+J20+K20*Supuestos!$D$13+IF(Y20="No",0,IF(AM20>0,AM20,G20))+AJ20,IF(V20="On rotation",F20+IF(AM20>0,AM20,G20)+H20+I20+J20+K20*Supuestos!$D$14,0)))))/12*Supuestos!$D$11 -> 37600 | AB20: =AA20+Z20 -> 37600 | AC20: =U20+AB20 -> 81200 | AD20: =M20-AC20 -> 14000 | AE20: =IF(V20="Expatriado",F20+IF(AM20>0,AM20,G20)+H20+I20+J20+K20*Supuestos!$D$14,IF(V20="Repatriado",F20+H20+J20+K20*Supuestos!$D$13+IF(Y20="No",0,IF(AM20>0,AM20,G20))+AJ20,IF(V20="Remote",F20,IF(V20="Local",F20+H20+J20+K20*Supuestos!$D$13+IF(Y20="No",0,IF(AM20>0,AM20,G20))+AJ20,IF(V20="On rotation",F20+IF(AM20>0,AM20,G20)+H20+I20+J20+K20*Supuestos!$D$14,0))))) -> 75200 | AF20: =IF(V20="Por definir","Definir paquete",IF(OR(V20="Remote",V20="On rotation"),"Completo",IF(W20="Por definir","Definir ciudad",IF(AND(OR(V20="Repatriado",V20="Local"),Y20="Por definir"),"Definir vivienda","Completo")))) -> Definir ciudad | AG20: =U20/Supuestos!$D$10 -> 7266.6667 | AH20: =AA20/Supuestos!$D$11 -> 6266.6667 | AI20: =AH20+Z20 -> 6266.6667 | AJ20: =0 -> 0 | AK20: =0 -> 0 | AL20: =0 -> 0 | AM20: =0 -> 0
D22: TOTAL — 9 POSICIONES | F22: =SUM(F12:F20) -> 1548000 | G22: =SUM(G12:G20) -> 180000 | H22: =SUM(H12:H20) -> 88000 | I22: =SUM(I12:I20) -> 92000 | J22: =SUM(J12:J20) -> 128400 | K22: =SUM(K12:K20) -> 286400 | L22: =SUM(L12:L20) -> 2322800 | M22: =SUM(M12:M20) -> 2396800 | ... U22: =SUM(U12:U20) -> 1018200 | Z22: =SUM(Z12:Z20) -> 0 | AA22: =SUM(AA12:AA20) -> 1150200 | AB22: =SUM(AB12:AB20) -> 1150200 | AC22: =SUM(AC12:AC20) -> 2168400 | AD22: =SUM(AD12:AD20) -> 228400 | AE22: =SUM(AE12:AE20) -> 2300400 | AG22: =SUM(AG12:AG20) -> 169700 | AH22: =SUM(AH12:AH20) -> 191700 | AI22: =SUM(AI12:AI20) -> 191700 | AJ22: =SUM(AJ12:AJ20) -> 204000 | AK22: =SUM(AK12:AK20) -> 0 | AL22: =SUM(AL12:AL20) -> 39 | AM22: =SUM(AM12:AM20) -> 12000

Sheet Mensual
C4: Costo mensual por persona
C6: M1–M6 como consultor | M7–M12 según paquete seleccionado; los costos únicos se cargan en M7
C7: USD | Expatriado: empresa cubre / neutraliza impuesto del país de trabajo; Repatriado: empleado asume su impuesto personal
C9: DETALLE MENSUAL POR PERSONA — ESCENARIO SELECCIONADO
C11: Person | D11: Position | E11: Package M7+ | F11: City | G11: M1 | H11: M2 | I11: M3 | J11: M4 | K11: M5 | L11: M6 | M11: M7 | N11: M8 | O11: M9 | P11: M10 | Q11: M11 | R11: M12 | S11: Year 1 | T11: Tratamiento fiscal M7+
C12: =Personal!E12 -> Martin del Castillo | D12: =Personal!D12 -> COO / PU General Manager | E12: =Personal!V12 -> Expatriado | F12: =Personal!W12 -> Por definir | G12: =Personal!U12/Supuestos!$D$10 -> 37666.667 | H12: =Personal!U12/Supuestos!$D$10 -> 37666.667 | I12: =Personal!U12/Supuestos!$D$10 -> 37666.667 | J12: =Personal!U12/Supuestos!$D$10 -> 37666.667 | K12: =Personal!U12/Supuestos!$D$10 -> 37666.667 | L12: =Personal!U12/Supuestos!$D$10 -> 37666.667 | M12: =Personal!AA12/Supuestos!$D$11+Personal!Z12 -> 43666.667 | N12: =Personal!AA12/Supuestos!$D$11 -> 43666.667 | O12: =Personal!AA12/Supuestos!$D$11 -> 43666.667 | P12: =Personal!AA12/Supuestos!$D$11 -> 43666.667 | Q12: =Personal!AA12/Supuestos!$D$11 -> 43666.667 | R12: =Personal!AA12/Supuestos!$D$11 -> 43666.667 | S12: =SUM(G12:R12) -> 488000 | T12: =IF(OR(E12="Expatriado",E12="On rotation"),"Empresa cubre / neutraliza impuesto del país de trabajo",IF(OR(E12="Repatriado",E12="Local"),"Empleado asume impuesto personal",IF(E12="Remote","Remote — sin beneficios","Definir paquete"))) -> Empresa cubre / neutraliza impuesto del país de trabajo
C13: =Personal!E13 -> Juan Conde | D13: =Personal!D13 -> EPCM & Engineering Manager | E13: =Personal!V13 -> Repatriado | F13: =Personal!W13 -> Maracaibo | G13: =Personal!U13/Supuestos!$D$10 -> 23500 | H13: =Personal!U13/Supuestos!$D$10 -> 23500 | I13: =Personal!U13/Supuestos!$D$10 -> 23500 | J13: =Personal!U13/Supuestos!$D$10 -> 23500 | K13: =Personal!U13/Supuestos!$D$10 -> 23500 | L13: =Personal!U13/Supuestos!$D$10 -> 23500 | M13: =Personal!AA13/Supuestos!$D$11+Personal!Z13 -> 28500 | N13: =Personal!AA13/Supuestos!$D$11 -> 28500 | O13: =Personal!AA13/Supuestos!$D$11 -> 28500 | P13: =Personal!AA13/Supuestos!$D$11 -> 28500 | Q13: =Personal!AA13/Supuestos!$D$11 -> 28500 | R13: =Personal!AA13/Supuestos!$D$11 -> 28500 | S13: =SUM(G13:R13) -> 312000 | T13: =IF(OR(E13="Expatriado",E13="On rotation"),"Empresa cubre / neutraliza impuesto del país de trabajo",IF(OR(E13="Repatriado",E13="Local"),"Empleado asume impuesto personal",IF(E13="Remote","Remote — sin beneficios","Definir paquete"))) -> Empleado asume impuesto personal
C14: =Personal!E14 -> Alexander Stulme | D14: =Personal!D14 -> Drilling & Well Services Manager | E14: =Personal!V14 -> Repatriado | F14: =Personal!W14 -> Maracaibo | G14: =Personal!U14/Supuestos!$D$10 -> 20500 | H14: =Personal!U14/Supuestos!$D$10 -> 20500 | I14: =Personal!U14/Supuestos!$D$10 -> 20500 | J14: =Personal!U14/Supuestos!$D$10 -> 20500 | K14: =Personal!U14/Supuestos!$D$10 -> 20500 | L14: =Personal!U14/Supuestos!$D$10 -> 20500 | M14: =Personal!AA14/Supuestos!$D$11+Personal!Z14 -> 22500 | N14: =Personal!AA14/Supuestos!$D$11 -> 22500 | O14: =Personal!AA14/Supuestos!$D$11 -> 22500 | P14: =Personal!AA14/Supuestos!$D$11 -> 22500 | Q14: =Personal!AA14/Supuestos!$D$11 -> 22500 | R14: =Personal!AA14/Supuestos!$D$11 -> 22500 | S14: =SUM(G14:R14) -> 258000 | T14: =IF(OR(E14="Expatriado",E14="On rotation"),"Empresa cubre / neutraliza impuesto del país de trabajo",IF(OR(E14="Repatriado",E14="Local"),"Empleado asume impuesto personal",IF(E14="Remote","Remote — sin beneficios","Definir paquete"))) -> Empleado asume impuesto personal
C15: =Personal!E15 -> Félix Valderrama | D15: =Personal!D15 -> Operations & Maintenance Manager | E15: =Personal!V15 -> Repatriado | F15: =Personal!W15 -> Maracaibo | G15: =Personal!U15/Supuestos!$D$10 -> 23500 | H15: =Personal!U15/Supuestos!$D$10 -> 23500 | I15: =Personal!U15/Supuestos!$D$10 -> 23500 | J15: =Personal!U15/Supuestos!$D$10 -> 23500 | K15: =Personal!U15/Supuestos!$D$10 -> 23500 | L15: =Personal!U15/Supuestos!$D$10 -> 23500 | M15: =Personal!AA15/Supuestos!$D$11+Personal!Z15 -> 28500 | N15: =Personal!AA15/Supuestos!$D$11 -> 28500 | O15: =Personal!AA15/Supuestos!$D$11 -> 28500 | P15: =Personal!AA15/Supuestos!$D$11 -> 28500 | Q15: =Personal!AA15/Supuestos!$D$11 -> 28500 | R15: =Personal!AA15/Supuestos!$D$11 -> 28500 | S15: =SUM(G15:R15) -> 312000 | T15: =IF(OR(E15="Expatriado",E15="On rotation"),"Empresa cubre / neutraliza impuesto del país de trabajo",IF(OR(E15="Repatriado",E15="Local"),"Empleado asume impuesto personal",IF(E15="Remote","Remote — sin beneficios","Definir paquete"))) -> Empleado asume impuesto personal
C16: =Personal!E16 -> Alan McKeon | D16: =Personal!D16 -> Technical Manager (Geosciences) | E16: =Personal!V16 -> Expatriado | F16: =Personal!W16 -> Maracaibo | G16: =Personal!U16/Supuestos!$D$10 -> 20500 | H16: =Personal!U16/Supuestos!$D$10 -> 20500 | I16: =Personal!U16/Supuestos!$D$10 -> 20500 | J16: =Personal!U16/Supuestos!$D$10 -> 20500 | K16: =Personal!U16/Supuestos!$D$10 -> 20500 | L16: =Personal!U16/Supuestos!$D$10 -> 20500 | M16: =Personal!AA16/Supuestos!$D$11+Personal!Z16 -> 22500 | N16: =Personal!AA16/Supuestos!$D$11 -> 22500 | O16: =Personal!AA16/Supuestos!$D$11 -> 22500 | P16: =Personal!AA16/Supuestos!$D$11 -> 22500 | Q16: =Personal!AA16/Supuestos!$D$11 -> 22500 | R16: =Personal!AA16/Supuestos!$D$11 -> 22500 | S16: =SUM(G16:R16) -> 258000 | T16: =IF(OR(E16="Expatriado",E16="On rotation"),"Empresa cubre / neutraliza impuesto del país de trabajo",IF(OR(E16="Repatriado",E16="Local"),"Empleado asume impuesto personal",IF(E16="Remote","Remote — sin beneficios","Definir paquete"))) -> Empresa cubre / neutraliza impuesto del país de trabajo
C17: =Personal!E17 -> JJI | D17: =Personal!D17 -> Reservoir Engineer | E17: =Personal!V17 -> Remote | F17: =Personal!W17 -> Remoto | G17: =Personal!U17/Supuestos!$D$10 -> 10000 | H17: =Personal!U17/Supuestos!$D$10 -> 10000 | I17: =Personal!U17/Supuestos!$D$10 -> 10000 | J17: =Personal!U17/Supuestos!$D$10 -> 10000 | K17: =Personal!U17/Supuestos!$D$10 -> 10000 | L17: =Personal!U17/Supuestos!$D$10 -> 10000 | M17: =Personal!AA17/Supuestos!$D$11+Personal!Z17 -> 10000 | N17: =Personal!AA17/Supuestos!$D$11 -> 10000 | O17: =Personal!AA17/Supuestos!$D$11 -> 10000 | P17: =Personal!AA17/Supuestos!$D$11 -> 10000 | Q17: =Personal!AA17/Supuestos!$D$11 -> 10000 | R17: =Personal!AA17/Supuestos!$D$11 -> 10000 | S17: =SUM(G17:R17) -> 120000 | T17: =IF(OR(E17="Expatriado",E17="On rotation"),"Empresa cubre / neutraliza impuesto del país de trabajo",IF(OR(E17="Repatriado",E17="Local"),"Empleado asume impuesto personal",IF(E17="Remote","Remote — sin beneficios","Definir paquete"))) -> Remote — sin beneficios
C18: =Personal!E18 -> Marcelo Dantas | D18: =Personal!D18 -> Rig Company Man | E18: =Personal!V18 -> On rotation | F18: =Personal!W18 -> Por definir | G18: =Personal!U18/Supuestos!$D$10 -> 20500 | H18: =Personal!U18/Supuestos!$D$10 -> 20500 | I18: =Personal!U18/Supuestos!$D$10 -> 20500 | J18: =Personal!U18/Supuestos!$D$10 -> 20500 | K18: =Personal!U18/Supuestos!$D$10 -> 20500 | L18: =Personal!U18/Supuestos!$D$10 -> 20500 | M18: =Personal!AA18/Supuestos!$D$11+Personal!Z18 -> 23500 | N18: =Personal!AA18/Supuestos!$D$11 -> 23500 | O18: =Personal!AA18/Supuestos!$D$11 -> 23500 | P18: =Personal!AA18/Supuestos!$D$11 -> 23500 | Q18: =Personal!AA18/Supuestos!$D$11 -> 23500 | R18: =Personal!AA18/Supuestos!$D$11 -> 23500 | S18: =SUM(G18:R18) -> 264000 | T18: =IF(OR(E18="Expatriado",E18="On rotation"),"Empresa cubre / neutraliza impuesto del país de trabajo",IF(OR(E18="Repatriado",E18="Local"),"Empleado asume impuesto personal",IF(E18="Remote","Remote — sin beneficios","Definir paquete"))) -> Empresa cubre / neutraliza impuesto del país de trabajo
C19: =Personal!E19 -> Jose Miguel | D19: =Personal!D19 -> Planning & PMO | E19: =Personal!V19 -> Local | F19: =Personal!W19 -> Maracaibo | G19: =Personal!U19/Supuestos!$D$10 -> 6266.6667 | H19: =Personal!U19/Supuestos!$D$10 -> 6266.6667 | I19: =Personal!U19/Supuestos!$D$10 -> 6266.6667 | J19: =Personal!U19/Supuestos!$D$10 -> 6266.6667 | K19: =Personal!U19/Supuestos!$D$10 -> 6266.6667 | L19: =Personal!U19/Supuestos!$D$10 -> 6266.6667 | M19: =Personal!AA19/Supuestos!$D$11+Personal!Z19 -> 6266.6667 | N19: =Personal!AA19/Supuestos!$D$11 -> 6266.6667 | O19: =Personal!AA19/Supuestos!$D$11 -> 6266.6667 | P19: =Personal!AA19/Supuestos!$D$11 -> 6266.6667 | Q19: =Personal!AA19/Supuestos!$D$11 -> 6266.6667 | R19: =Personal!AA19/Supuestos!$D$11 -> 6266.6667 | S19: =SUM(G19:R19) -> 75200 | T19: =IF(OR(E19="Expatriado",E19="On rotation"),"Empresa cubre / neutraliza impuesto del país de trabajo",IF(OR(E19="Repatriado",E19="Local"),"Empleado asume impuesto personal",IF(E19="Remote","Remote — sin beneficios","Definir paquete"))) -> Empleado asume impuesto personal
C20: =Personal!E20 -> TBD | D20: =Personal!D20 -> Operations Support | E20: =Personal!V20 -> Local | F20: =Personal!W20 -> Por definir | G20: =Personal!U20/Supuestos!$D$10 -> 7266.6667 | H20: =Personal!U20/Supuestos!$D$10 -> 7266.6667 | I20: =Personal!U20/Supuestos!$D$10 -> 7266.6667 | J20: =Personal!U20/Supuestos!$D$10 -> 7266.6667 | K20: =Personal!U20/Supuestos!$D$10 -> 7266.6667 | L20: =Personal!U20/Supuestos!$D$10 -> 7266.6667 | M20: =Personal!AA20/Supuestos!$D$11+Personal!Z20 -> 6266.6667 | N20: =Personal!AA20/Supuestos!$D$11 -> 6266.6667 | O20: =Personal!AA20/Supuestos!$D$11 -> 6266.6667 | P20: =Personal!AA20/Supuestos!$D$11 -> 6266.6667 | Q20: =Personal!AA20/Supuestos!$D$11 -> 6266.6667 | R20: =Personal!AA20/Supuestos!$D$11 -> 6266.6667 | S20: =SUM(G20:R20) -> 81200 | T20: =IF(OR(E20="Expatriado",E20="On rotation"),"Empresa cubre / neutraliza impuesto del país de trabajo",IF(OR(E20="Repatriado",E20="Local"),"Empleado asume impuesto personal",IF(E20="Remote","Remote — sin beneficios","Definir paquete"))) -> Empleado asume impuesto personal
C22: TOTAL — 9 POSICIONES | G22: =SUM(G12:G20) -> 169700 | H22: =SUM(H12:H20) -> 169700 | I22: =SUM(I12:I20) -> 169700 | J22: =SUM(J12:J20) -> 169700 | K22: =SUM(K12:K20) -> 169700 | L22: =SUM(L12:L20) -> 169700 | M22: =SUM(M12:M20) -> 191700 | N22: =SUM(N12:N20) -> 191700 | ... S22: =SUM(S12:S20) -> 2168400
C25: COSTO TOTAL POR MES — COMPARACIÓN DE ESCENARIOS
C26: Escenario | D26: M1 | E26: M2 | F26: M3 | G26: M4 | H26: M5 | I26: M6 | J26: M7 | K26: M8 | L26: M9 | M26: M10 | N26: M11 | O26: M12 | P26: Year 1 | Q26: Tratamiento fiscal desde M7
C27: Selección actual por persona | D27: =Personal!U22/Supuestos!$D$10 -> 169700 | E27: =Personal!U22/Supuestos!$D$10 -> 169700 | F27: =Personal!U22/Supuestos!$D$10 -> 169700 | G27: =Personal!U22/Supuestos!$D$10 -> 169700 | H27: =Personal!U22/Supuestos!$D$10 -> 169700 | I27: =Personal!U22/Supuestos!$D$10 -> 169700 | J27: =M22 -> 191700 | K27: =N22 -> 191700 | L27: =O22 -> 191700 | M27: =P22 -> 191700 | N27: =Q22 -> 191700 | O27: =R22 -> 191700 | P27: =SUM(D27:O27) -> 2168400 | Q27: Según selección individual
C28: Todos expatriados | D28: =Personal!U22/Supuestos!$D$10 -> 169700 | E28: =Personal!U22/Supuestos!$D$10 -> 169700 | F28: =Personal!U22/Supuestos!$D$10 -> 169700 | G28: =Personal!U22/Supuestos!$D$10 -> 169700 | H28: =Personal!U22/Supuestos!$D$10 -> 169700 | I28: =Personal!U22/Supuestos!$D$10 -> 169700 | J28: =(SUM(Personal!F12:F20)+SUM(Personal!G12:G20)+SUM(Personal!H12:H20)+SUM(Personal!I12:I20)+SUM(Personal!J12:J20)+SUM(Personal!K12:K20)*Supuestos!$D$14)/12 -> 193566.67 | K28: =(SUM(Personal!F12:F20)+SUM(Personal!G12:G20)+SUM(Personal!H12:H20)+SUM(Personal!I12:I20)+SUM(Personal!J12:J20)+SUM(Personal!K12:K20)*Supuestos!$D$14)/12 -> 193566.67 | L28: =(SUM(Personal!F12:F20)+SUM(Personal!G12:G20)+SUM(Personal!H12:H20)+SUM(Personal!I12:I20)+SUM(Personal!J12:J20)+SUM(Personal!K12:K20)*Supuestos!$D$14)/12 -> 193566.67 | M28: =(SUM(Personal!F12:F20)+SUM(Personal!G12:G20)+SUM(Personal!H12:H20)+SUM(Personal!I12:I20)+SUM(Personal!J12:J20)+SUM(Personal!K12:K20)*Supuestos!$D$14)/12 -> 193566.67 | N28: =(SUM(Personal!F12:F20)+SUM(Personal!G12:G20)+SUM(Personal!H12:H20)+SUM(Personal!I12:I20)+SUM(Personal!J12:J20)+SUM(Personal!K12:K20)*Supuestos!$D$14)/12 -> 193566.67 | O28: =(SUM(Personal!F12:F20)+SUM(Personal!G12:G20)+SUM(Personal!H12:H20)+SUM(Personal!I12:I20)+SUM(Personal!J12:J20)+SUM(Personal!K12:K20)*Supuestos!$D$14)/12 -> 193566.67 | P28: =SUM(D28:O28) -> 2179600 | Q28: Empresa cubre / neutraliza impuesto del país de trabajo
C29: Todos repatriados — con housing | D29: =Personal!U22/Supuestos!$D$10 -> 169700 | E29: =Personal!U22/Supuestos!$D$10 -> 169700 | F29: =Personal!U22/Supuestos!$D$10 -> 169700 | G29: =Personal!U22/Supuestos!$D$10 -> 169700 | H29: =Personal!U22/Supuestos!$D$10 -> 169700 | I29: =Personal!U22/Supuestos!$D$10 -> 169700 | J29: =(SUM(Personal!F12:F20)+SUM(Personal!G12:G20)+SUM(Personal!H12:H20)+SUM(Personal!J12:J20)+SUM(Personal!K12:K20)*Supuestos!$D$13)/12 -> 162033.33 | K29: =(SUM(Personal!F12:F20)+SUM(Personal!G12:G20)+SUM(Personal!H12:H20)+SUM(Personal!J12:J20)+SUM(Personal!K12:K20)*Supuestos!$D$13)/12 -> 162033.33 | L29: =(SUM(Personal!F12:F20)+SUM(Personal!G12:G20)+SUM(Personal!H12:H20)+SUM(Personal!J12:J20)+SUM(Personal!K12:K20)*Supuestos!$D$13)/12 -> 162033.33 | M29: =(SUM(Personal!F12:F20)+SUM(Personal!G12:G20)+SUM(Personal!H12:H20)+SUM(Personal!J12:J20)+SUM(Personal!K12:K20)*Supuestos!$D$13)/12 -> 162033.33 | N29: =(SUM(Personal!F12:F20)+SUM(Personal!G12:G20)+SUM(Personal!H12:H20)+SUM(Personal!J12:J20)+SUM(Personal!K12:K20)*Supuestos!$D$13)/12 -> 162033.33 | O29: =(SUM(Personal!F12:F20)+SUM(Personal!G12:G20)+SUM(Personal!H12:H20)+SUM(Personal!J12:J20)+SUM(Personal!K12:K20)*Supuestos!$D$13)/12 -> 162033.33 | P29: =SUM(D29:O29) -> 1990400 | Q29: Empleado asume impuesto personal
C30: Todos repatriados — sin housing | D30: =Personal!U22/Supuestos!$D$10 -> 169700 | E30: =Personal!U22/Supuestos!$D$10 -> 169700 | F30: =Personal!U22/Supuestos!$D$10 -> 169700 | G30: =Personal!U22/Supuestos!$D$10 -> 169700 | H30: =Personal!U22/Supuestos!$D$10 -> 169700 | I30: =Personal!U22/Supuestos!$D$10 -> 169700 | J30: =(SUM(Personal!F12:F20)+SUM(Personal!H12:H20)+SUM(Personal!J12:J20)+SUM(Personal!K12:K20)*Supuestos!$D$13)/12 -> 147033.33 | K30: =(SUM(Personal!F12:F20)+SUM(Personal!H12:H20)+SUM(Personal!J12:J20)+SUM(Personal!K12:K20)*Supuestos!$D$13)/12 -> 147033.33 | L30: =(SUM(Personal!F12:F20)+SUM(Personal!H12:H20)+SUM(Personal!J12:J20)+SUM(Personal!K12:K20)*Supuestos!$D$13)/12 -> 147033.33 | M30: =(SUM(Personal!F12:F20)+SUM(Personal!H12:H20)+SUM(Personal!J12:J20)+SUM(Personal!K12:K20)*Supuestos!$D$13)/12 -> 147033.33 | N30: =(SUM(Personal!F12:F20)+SUM(Personal!H12:H20)+SUM(Personal!J12:J20)+SUM(Personal!K12:K20)*Supuestos!$D$13)/12 -> 147033.33 | O30: =(SUM(Personal!F12:F20)+SUM(Personal!H12:H20)+SUM(Personal!J12:J20)+SUM(Personal!K12:K20)*Supuestos!$D$13)/12 -> 147033.33 | P30: =SUM(D30:O30) -> 1900400 | Q30: Empleado asume impuesto personal

Sheet Definiciones
C4: Definición de los paquetes
C6: Alcance presupuestario, criterios de clasificación y elementos de transición
C7: Documento de trabajo institucional — sujeto a aprobación legal, fiscal y de Recursos Humanos
C9: PAQUETE CONSULTOR — MESES 1 A 6
C10: • Relación presupuestaria: honorario de consultoría equivalente a 6/12 del salario base anual de referencia.
C11: • Beneficios / reembolsos incluidos: housing, seguro médico, home leave y vehículo, todos prorrateados por seis meses.
C12: • Tax & Social venezolano: factor 0% por instrucción gerencial. No constituye opinión jurídica ni fiscal.
C13: • Contrato: debe documentar entregables, facturación, moneda, reembolsos, seguros y terminación, sin crear una clasificación laboral incorrecta.
C15: PAQUETE REPATRIADO — DESDE EL MES 7
C16: • Compensación recurrente pagada por la empresa: salario base, seguro médico y vehículo.
C17: • Impuesto personal: lo asume el repatriado. El factor de Tax & Social pagado por la empresa es 0% por defecto, salvo cargas patronales obligatorias.
C18: • Housing: condicional. Política inicial editable: Caracas = Sí; Maracaibo = No. Un override individual prevalece sobre la regla automática.
... C32: La visa o admisión como turista normalmente no debe asumirse como autorización de trabajo. Además, la ausencia de una carga fiscal venezolana no puede determinarse únicamente por los primeros seis meses o por el estatus migratorio. El archivo es una herramienta de presupuesto: antes de contratar, movilizar o pagar, solicitar un dictamen local escrito sobre inmigración, clasificación laboral, establecimiento permanente, retenciones, impuesto sobre la renta y seguridad social.
